Traceback (most recent call last):
  File "<frozen runpy>", line 198, in _run_module_as_main
  File "<frozen runpy>", line 88, in _run_code
  File "/Users/yeseniapuga/.espressif/python_env/idf5.3_py3.11_env/lib/python3.11/site-packages/esptool/__main__.py", line 9, in <module>
    esptool._main()
  File "/Users/yeseniapuga/.espressif/python_env/idf5.3_py3.11_env/lib/python3.11/site-packages/esptool/__init__.py", line 1170, in _main
    main()
  File "/Users/yeseniapuga/.espressif/python_env/idf5.3_py3.11_env/lib/python3.11/site-packages/esptool/__init__.py", line 721, in main
    esp = esp or get_default_connected_device(
                 ^^^^^^^^^^^^^^^^^^^^^^^^^^^^^
  File "/Users/yeseniapuga/.espressif/python_env/idf5.3_py3.11_env/lib/python3.11/site-packages/esptool/__init__.py", line 1054, in get_default_connected_device
    _esp = chip_class(each_port, initial_baud, trace)
           ^^^^^^^^^^^^^^^^^^^^^^^^^^^^^^^^^^^^^^^^^^
  File "/Users/yeseniapuga/.espressif/python_env/idf5.3_py3.11_env/lib/python3.11/site-packages/esptool/loader.py", line 313, in __init__
    self._port.open()
  File "/Users/yeseniapuga/.espressif/python_env/idf5.3_py3.11_env/lib/python3.11/site-packages/serial/serialposix.py", line 332, in open
    self._reconfigure_port(force_update=True)
  File "/Users/yeseniapuga/.espressif/python_env/idf5.3_py3.11_env/lib/python3.11/site-packages/serial/serialposix.py", line 517, in _reconfigure_port
    termios.tcsetattr(
termios.error: (22, 'Invalid argument')
CMake Error at run_serial_tool.cmake:66 (message):
  
  /Users/yeseniapuga/.espressif/python_env/idf5.3_py3.11_env/bin/python;;/Users/yeseniapuga/esp/esp-idf/components/esptool_py/esptool/esptool.py;--chip;esp32
  failed.



